Workbook

Sheet calcul des chants
B4: Ref client : | F4: Ref chantier : | M4: De : | P4: Page : | Q4: /
A6: Nature du produit souhaité:
A8: Nature du panneau CP,Agglo,MDF,Mélaminé | C8: Marque/couleur/références | G8: Epaisseur (mm) | I8: Finition | K8: Sens de fil
K10: OUI : | M10: NON :
A13: Références | B13: Longueur ou sens du fil (cotes finies en mm) | C13: largeur ou fil travers (cotes finies en mm) | D13: Qté | E13: 0,8mm | F13: x | G13: 2mm: | I13: Calcul du métré de chants | J13: Description I | M13: Description II | P13: Description III
E14: Autre type:
E15: CHANTS (voir croquis)
E16: A | F16: B | G16: C | H16: D
I17: =(IF(E17="x",(B17+50)/1000,0)+IF(F17="x",(B17+50)/1000,0)+IF(G17="x",(C17+50)/1000,0)+IF(H17="x",(C17+50)/1000,0))*D17
I18: =(IF(E18="x",(B18+50)/1000,0)+IF(F18="x",(B18+50)/1000,0)+IF(G18="x",(C18+50)/1000,0)+IF(H18="x",(C18+50)/1000,0))*D18
I19: =(IF(E19="x",(B19+50)/1000,0)+IF(F19="x",(B19+50)/1000,0)+IF(G19="x",(C19+50)/1000,0)+IF(H19="x",(C19+50)/1000,0))*D19
I20: =(IF(E20="x",(B20+50)/1000,0)+IF(F20="x",(B20+50)/1000,0)+IF(G20="x",(C20+50)/1000,0)+IF(H20="x",(C20+50)/1000,0))*D20
I21: =(IF(E21="x",(B21+50)/1000,0)+IF(F21="x",(B21+50)/1000,0)+IF(G21="x",(C21+50)/1000,0)+IF(H21="x",(C21+50)/1000,0))*D21
I22: =(IF(E22="x",(B22+50)/1000,0)+IF(F22="x",(B22+50)/1000,0)+IF(G22="x",(C22+50)/1000,0)+IF(H22="x",(C22+50)/1000,0))*D22
I23: =(IF(E23="x",(B23+50)/1000,0)+IF(F23="x",(B23+50)/1000,0)+IF(G23="x",(C23+50)/1000,0)+IF(H23="x",(C23+50)/1000,0))*D23
I24: =(IF(E24="x",(B24+50)/1000,0)+IF(F24="x",(B24+50)/1000,0)+IF(G24="x",(C24+50)/1000,0)+IF(H24="x",(C24+50)/1000,0))*D24
I25: =(IF(E25="x",(B25+50)/1000,0)+IF(F25="x",(B25+50)/1000,0)+IF(G25="x",(C25+50)/1000,0)+IF(H25="x",(C25+50)/1000,0))*D25
I26: =(IF(E26="x",(B26+50)/1000,0)+IF(F26="x",(B26+50)/1000,0)+IF(G26="x",(C26+50)/1000,0)+IF(H26="x",(C26+50)/1000,0))*D26
I27: =(IF(E27="x",(B27+50)/1000,0)+IF(F27="x",(B27+50)/1000,0)+IF(G27="x",(C27+50)/1000,0)+IF(H27="x",(C27+50)/1000,0))*D27
I28: =(IF(E28="x",(B28+50)/1000,0)+IF(F28="x",(B28+50)/1000,0)+IF(G28="x",(C28+50)/1000,0)+IF(H28="x",(C28+50)/1000,0))*D28
... I81: =(IF(E81="x",(B81+50)/1000,0)+IF(F81="x",(B81+50)/1000,0)+IF(G81="x",(C81+50)/1000,0)+IF(H81="x",(C81+50)/1000,0))*D81
E82: Total de chant | I82: =SUM(I17:I81)

Sheet Optimisateur
B2: Piece | C2: Panneaux | D2: Longueur | E2: Largeur | F2: Qté mini. | G2: Sens du fil | H2: Cht G | I2: Cht D | J2: Cht H | K2: Cht B | L2: graphique etiquette | M2: Client | N2: Ref/Salon | O2: Meuble | P2: Usinage | Q2: Information | T2: chant | U2: chant cute rite | V2: FORMULE
B3: =IF(D3="","",'calcul des chants'!A17) | C3: =IF('calcul des chants'!B17<>"",'calcul des chants'!$A$10,"") | D3: =IF(C3="","",'calcul des chants'!B17) | E3: =IF(D3="","",'calcul des chants'!C17) | F3: =IF(E3="","",'calcul des chants'!D17) | H3: =IF('calcul des chants'!E17=Optimisateur!$T$3,Optimisateur!$U$3,"") | I3: =IF('calcul des chants'!F17=Optimisateur!$T$3,Optimisateur!$U$3,"") | J3: =IF('calcul des chants'!G17=Optimisateur!$T$3,Optimisateur!$U$3,"") | K3: =IF('calcul des chants'!H17=Optimisateur!$T$3,Optimisateur!$U$3,"") | M3: =IF(C3="","",'calcul des chants'!$C$4) | N3: =IF(D3="","",'calcul des chants'!$I$4) | O3: =IF(E3="","",'calcul des chants'!J17) | P3: =IF(F3="","",'calcul des chants'!M17) | Q3: =IF(G3="","",'calcul des chants'!P17) | T3: X | U3: PVC-23-1
B4: =IF(D4="","",'calcul des chants'!A18) | C4: =IF('calcul des chants'!B18<>"",'calcul des chants'!$A$10,"") | D4: =IF(C4="","",'calcul des chants'!B18) | E4: =IF(D4="","",'calcul des chants'!C18) | F4: =IF(E4="","",'calcul des chants'!D18) | H4: =IF('calcul des chants'!E18=Optimisateur!$T$3,Optimisateur!$U$3,"") | I4: =IF('calcul des chants'!F18=Optimisateur!$T$3,Optimisateur!$U$3,"") | J4: =IF('calcul des chants'!G18=Optimisateur!$T$3,Optimisateur!$U$3,"") | K4: =IF('calcul des chants'!H18=Optimisateur!$T$3,Optimisateur!$U$3,"") | M4: =IF(C4="","",'calcul des chants'!$C$4) | N4: =IF(D4="","",'calcul des chants'!$Z$4) | O4: =IF(E4="","",'calcul des chants'!J18) | P4: =IF(F4="","",'calcul des chants'!M18) | Q4: =IF(G4="","",'calcul des chants'!P18)
B5: =IF(D5="","",'calcul des chants'!A19) | C5: =IF('calcul des chants'!B19<>"",'calcul des chants'!$A$10,"") | D5: =IF(C5="","",'calcul des chants'!B19) | E5: =IF(D5="","",'calcul des chants'!C19) | F5: =IF(E5="","",'calcul des chants'!D19) | H5: =IF('calcul des chants'!E19=Optimisateur!$T$3,Optimisateur!$U$3,"") | I5: =IF('calcul des chants'!F19=Optimisateur!$T$3,Optimisateur!$U$3,"") | J5: =IF('calcul des chants'!G19=Optimisateur!$T$3,Optimisateur!$U$3,"") | K5: =IF('calcul des chants'!H19=Optimisateur!$T$3,Optimisateur!$U$3,"") | M5: =IF(C5="","",'calcul des chants'!$C$4) | N5: =IF(D5="","",'calcul des chants'!$Z$4) | O5: =IF(E5="","",'calcul des chants'!J19) | P5: =IF(F5="","",'calcul des chants'!M19) | Q5: =IF(G5="","",'calcul des chants'!P19)
B6: =IF(D6="","",'calcul des chants'!A20) | C6: =IF('calcul des chants'!B20<>"",'calcul des chants'!$A$10,"") | D6: =IF(C6="","",'calcul des chants'!B20) | E6: =IF(D6="","",'calcul des chants'!C20) | F6: =IF(E6="","",'calcul des chants'!D20) | H6: =IF('calcul des chants'!E20=Optimisateur!$T$3,Optimisateur!$U$3,"") | I6: =IF('calcul des chants'!F20=Optimisateur!$T$3,Optimisateur!$U$3,"") | J6: =IF('calcul des chants'!G20=Optimisateur!$T$3,Optimisateur!$U$3,"") | K6: =IF('calcul des chants'!H20=Optimisateur!$T$3,Optimisateur!$U$3,"") | M6: =IF(C6="","",'calcul des chants'!$C$4) | N6: =IF(D6="","",'calcul des chants'!$Z$4) | O6: =IF(E6="","",'calcul des chants'!J20) | P6: =IF(F6="","",'calcul des chants'!M20) | Q6: =IF(G6="","",'calcul des chants'!P20)
B7: =IF(D7="","",'calcul des chants'!A21) | C7: =IF('calcul des chants'!B21<>"",'calcul des chants'!$A$10,"") | D7: =IF(C7="","",'calcul des chants'!B21) | E7: =IF(D7="","",'calcul des chants'!C21) | F7: =IF(E7="","",'calcul des chants'!D21) | H7: =IF('calcul des chants'!E21=Optimisateur!$T$3,Optimisateur!$U$3,"") | I7: =IF('calcul des chants'!F21=Optimisateur!$T$3,Optimisateur!$U$3,"") | J7: =IF('calcul des chants'!G21=Optimisateur!$T$3,Optimisateur!$U$3,"") | K7: =IF('calcul des chants'!H21=Optimisateur!$T$3,Optimisateur!$U$3,"") | M7: =IF(C7="","",'calcul des chants'!$C$4) | N7: =IF(D7="","",'calcul des chants'!$Z$4) | O7: =IF(E7="","",'calcul des chants'!J21) | P7: =IF(F7="","",'calcul des chants'!M21) | Q7: =IF(G7="","",'calcul des chants'!P21)
B8: =IF(D8="","",'calcul des chants'!A22) | C8: =IF('calcul des chants'!B22<>"",'calcul des chants'!$A$10,"") | D8: =IF(C8="","",'calcul des chants'!B22) | E8: =IF(D8="","",'calcul des chants'!C22) | F8: =IF(E8="","",'calcul des chants'!D22) | H8: =IF('calcul des chants'!E22=Optimisateur!$T$3,Optimisateur!$U$3,"") | I8: =IF('calcul des chants'!F22=Optimisateur!$T$3,Optimisateur!$U$3,"") | J8: =IF('calcul des chants'!G22=Optimisateur!$T$3,Optimisateur!$U$3,"") | K8: =IF('calcul des chants'!H22=Optimisateur!$T$3,Optimisateur!$U$3,"") | M8: =IF(C8="","",'calcul des chants'!$C$4) | N8: =IF(D8="","",'calcul des chants'!$Z$4) | O8: =IF(E8="","",'calcul des chants'!J22) | P8: =IF(F8="","",'calcul des chants'!M22) | Q8: =IF(G8="","",'calcul des chants'!P22)
B9: =IF(D9="","",'calcul des chants'!A23) | C9: =IF('calcul des chants'!B23<>"",'calcul des chants'!$A$10,"") | D9: =IF(C9="","",'calcul des chants'!B23) | E9: =IF(D9="","",'calcul des chants'!C23) | F9: =IF(E9="","",'calcul des chants'!D23) | H9: =IF('calcul des chants'!E23=Optimisateur!$T$3,Optimisateur!$U$3,"") | I9: =IF('calcul des chants'!F23=Optimisateur!$T$3,Optimisateur!$U$3,"") | J9: =IF('calcul des chants'!G23=Optimisateur!$T$3,Optimisateur!$U$3,"") | K9: =IF('calcul des chants'!H23=Optimisateur!$T$3,Optimisateur!$U$3,"") | M9: =IF(C9="","",'calcul des chants'!$C$4) | N9: =IF(D9="","",'calcul des chants'!$Z$4) | O9: =IF(E9="","",'calcul des chants'!J23) | P9: =IF(F9="","",'calcul des chants'!M23) | Q9: =IF(G9="","",'calcul des chants'!P23) | U9: PVC-23-1-BLANC
B10: =IF(D10="","",'calcul des chants'!A24) | C10: =IF('calcul des chants'!B24<>"",'calcul des chants'!$A$10,"") | D10: =IF(C10="","",'calcul des chants'!B24) | E10: =IF(D10="","",'calcul des chants'!C24) | F10: =IF(E10="","",'calcul des chants'!D24) | H10: =IF('calcul des chants'!E24=Optimisateur!$T$3,Optimisateur!$U$3,"") | I10: =IF('calcul des chants'!F24=Optimisateur!$T$3,Optimisateur!$U$3,"") | J10: =IF('calcul des chants'!G24=Optimisateur!$T$3,Optimisateur!$U$3,"") | K10: =IF('calcul des chants'!H24=Optimisateur!$T$3,Optimisateur!$U$3,"") | M10: =IF(C10="","",'calcul des chants'!$C$4) | N10: =IF(D10="","",'calcul des chants'!$Z$4) | O10: =IF(E10="","",'calcul des chants'!J24) | P10: =IF(F10="","",'calcul des chants'!M24) | Q10: =IF(G10="","",'calcul des chants'!P24) | U10: PVC-23-1-UNI
B11: =IF(D11="","",'calcul des chants'!A25) | C11: =IF('calcul des chants'!B25<>"",'calcul des chants'!$A$10,"") | D11: =IF(C11="","",'calcul des chants'!B25) | E11: =IF(D11="","",'calcul des chants'!C25) | F11: =IF(E11="","",'calcul des chants'!D25) | H11: =IF('calcul des chants'!E25=Optimisateur!$T$3,Optimisateur!$U$3,"") | I11: =IF('calcul des chants'!F25=Optimisateur!$T$3,Optimisateur!$U$3,"") | J11: =IF('calcul des chants'!G25=Optimisateur!$T$3,Optimisateur!$U$3,"") | K11: =IF('calcul des chants'!H25=Optimisateur!$T$3,Optimisateur!$U$3,"") | M11: =IF(C11="","",'calcul des chants'!$C$4) | N11: =IF(D11="","",'calcul des chants'!$Z$4) | O11: =IF(E11="","",'calcul des chants'!J25) | P11: =IF(F11="","",'calcul des chants'!M25) | Q11: =IF(G11="","",'calcul des chants'!P25) | U11: PVC-23-2-BLANC
B12: =IF(D12="","",'calcul des chants'!A26) | C12: =IF('calcul des chants'!B26<>"",'calcul des chants'!$A$10,"") | D12: =IF(C12="","",'calcul des chants'!B26) | E12: =IF(D12="","",'calcul des chants'!C26) | F12: =IF(E12="","",'calcul des chants'!D26) | H12: =IF('calcul des chants'!E26=Optimisateur!$T$3,Optimisateur!$U$3,"") | I12: =IF('calcul des chants'!F26=Optimisateur!$T$3,Optimisateur!$U$3,"") | J12: =IF('calcul des chants'!G26=Optimisateur!$T$3,Optimisateur!$U$3,"") | K12: =IF('calcul des chants'!H26=Optimisateur!$T$3,Optimisateur!$U$3,"") | M12: =IF(C12="","",'calcul des chants'!$C$4) | N12: =IF(D12="","",'calcul des chants'!$Z$4) | O12: =IF(E12="","",'calcul des chants'!J26) | P12: =IF(F12="","",'calcul des chants'!M26) | Q12: =IF(G12="","",'calcul des chants'!P26) | U12: PVC-23-2-UNI
B13: =IF(D13="","",'calcul des chants'!A28) | C13: =IF('calcul des chants'!B27<>"",'calcul des chants'!$A$10,"") | D13: =IF(C13="","",'calcul des chants'!B27) | E13: =IF(D13="","",'calcul des chants'!C27) | F13: =IF(E13="","",'calcul des chants'!D27) | H13: =IF('calcul des chants'!E27=Optimisateur!$T$3,Optimisateur!$U$3,"") | I13: =IF('calcul des chants'!F27=Optimisateur!$T$3,Optimisateur!$U$3,"") | J13: =IF('calcul des chants'!G27=Optimisateur!$T$3,Optimisateur!$U$3,"") | K13: =IF('calcul des chants'!H27=Optimisateur!$T$3,Optimisateur!$U$3,"") | M13: =IF(C13="","",'calcul des chants'!$C$4) | N13: =IF(D13="","",'calcul des chants'!$Z$4) | O13: =IF(E13="","",'calcul des chants'!J27) | P13: =IF(F13="","",'calcul des chants'!M27) | Q13: =IF(G13="","",'calcul des chants'!P27)
B14: =IF(D14="","",'calcul des chants'!#REF!) | C14: =IF('calcul des chants'!B28<>"",'calcul des chants'!$A$10,"") | D14: =IF(C14="","",'calcul des chants'!B28) | E14: =IF(D14="","",'calcul des chants'!C28) | F14: =IF(E14="","",'calcul des chants'!D28) | H14: =IF('calcul des chants'!E28=Optimisateur!$T$3,Optimisateur!$U$3,"") | I14: =IF('calcul des chants'!F28=Optimisateur!$T$3,Optimisateur!$U$3,"") | J14: =IF('calcul des chants'!G28=Optimisateur!$T$3,Optimisateur!$U$3,"") | K14: =IF('calcul des chants'!H28=Optimisateur!$T$3,Optimisateur!$U$3,"") | M14: =IF(C14="","",'calcul des chants'!$C$4) | N14: =IF(D14="","",'calcul des chants'!$Z$4) | O14: =IF(E14="","",'calcul des chants'!J28) | P14: =IF(F14="","",'calcul des chants'!M28) | Q14: =IF(G14="","",'calcul des chants'!P28)
B15: =IF(D15="","",'calcul des chants'!A29) | C15: =IF('calcul des chants'!B29<>"",'calcul des chants'!$A$10,"") | D15: =IF(C15="","",'calcul des chants'!B29) | E15: =IF(D15="","",'calcul des chants'!C29) | F15: =IF(E15="","",'calcul des chants'!D29) | H15: =IF('calcul des chants'!E29=Optimisateur!$T$3,Optimisateur!$U$3,"") | I15: =IF('calcul des chants'!F29=Optimisateur!$T$3,Optimisateur!$U$3,"") | J15: =IF('calcul des chants'!G29=Optimisateur!$T$3,Optimisateur!$U$3,"") | K15: =IF('calcul des chants'!H29=Optimisateur!$T$3,Optimisateur!$U$3,"") | M15: =IF(C15="","",'calcul des chants'!$C$4) | N15: =IF(D15="","",'calcul des chants'!$Z$4) | O15: =IF(E15="","",'calcul des chants'!J29) | P15: =IF(F15="","",'calcul des chants'!M29) | Q15: =IF(G15="","",'calcul des chants'!P29)
B16: =IF(D16="","",'calcul des chants'!A30) | C16: =IF('calcul des chants'!B30<>"",'calcul des chants'!$A$10,"") | D16: =IF(C16="","",'calcul des chants'!B30) | E16: =IF(D16="","",'calcul des chants'!C30) | F16: =IF(E16="","",'calcul des chants'!D30) | H16: =IF('calcul des chants'!E30=Optimisateur!$T$3,Optimisateur!$U$3,"") | I16: =IF('calcul des chants'!F30=Optimisateur!$T$3,Optimisateur!$U$3,"") | J16: =IF('calcul des chants'!G30=Optimisateur!$T$3,Optimisateur!$U$3,"") | K16: =IF('calcul des chants'!H30=Optimisateur!$T$3,Optimisateur!$U$3,"") | M16: =IF(C16="","",'calcul des chants'!$C$4) | N16: =IF(D16="","",'calcul des chants'!$Z$4) | O16: =IF(E16="","",'calcul des chants'!J30) | P16: =IF(F16="","",'calcul des chants'!M30) | Q16: =IF(G16="","",'calcul des chants'!P30)
B17: =IF(D17="","",'calcul des chants'!A31) | C17: =IF('calcul des chants'!B31<>"",'calcul des chants'!$A$10,"") | D17: =IF(C17="","",'calcul des chants'!B31) | E17: =IF(D17="","",'calcul des chants'!C31) | F17: =IF(E17="","",'calcul des chants'!D31) | H17: =IF('calcul des chants'!E31=Optimisateur!$T$3,Optimisateur!$U$3,"") | I17: =IF('calcul des chants'!F31=Optimisateur!$T$3,Optimisateur!$U$3,"") | J17: =IF('calcul des chants'!G31=Optimisateur!$T$3,Optimisateur!$U$3,"") | K17: =IF('calcul des chants'!H31=Optimisateur!$T$3,Optimisateur!$U$3,"") | M17: =IF(C17="","",'calcul des chants'!$C$4) | N17: =IF(D17="","",'calcul des chants'!$Z$4) | O17: =IF(E17="","",'calcul des chants'!J31) | P17: =IF(F17="","",'calcul des chants'!M31) | Q17: =IF(G17="","",'calcul des chants'!P31)
B18: =IF(D18="","",'calcul des chants'!A32) | C18: =IF('calcul des chants'!B32<>"",'calcul des chants'!$A$10,"") | D18: =IF(C18="","",'calcul des chants'!B32) | E18: =IF(D18="","",'calcul des chants'!C32) | F18: =IF(E18="","",'calcul des chants'!D32) | H18: =IF('calcul des chants'!E32=Optimisateur!$T$3,Optimisateur!$U$3,"") | I18: =IF('calcul des chants'!F32=Optimisateur!$T$3,Optimisateur!$U$3,"") | J18: =IF('calcul des chants'!G32=Optimisateur!$T$3,Optimisateur!$U$3,"") | K18: =IF('calcul des chants'!H32=Optimisateur!$T$3,Optimisateur!$U$3,"") | M18: =IF(C18="","",'calcul des chants'!$C$4) | N18: =IF(D18="","",'calcul des chants'!$Z$4) | O18: =IF(E18="","",'calcul des chants'!J32) | P18: =IF(F18="","",'calcul des chants'!M32) | Q18: =IF(G18="","",'calcul des chants'!P32)
B19: =IF(D19="","",'calcul des chants'!A33) | C19: =IF('calcul des chants'!B33<>"",'calcul des chants'!$A$10,"") | D19: =IF(C19="","",'calcul des chants'!B33) | E19: =IF(D19="","",'calcul des chants'!C33) | F19: =IF(E19="","",'calcul des chants'!D33) | H19: =IF('calcul des chants'!E33=Optimisateur!$T$3,Optimisateur!$U$3,"") | I19: =IF('calcul des chants'!F33=Optimisateur!$T$3,Optimisateur!$U$3,"") | J19: =IF('calcul des chants'!G33=Optimisateur!$T$3,Optimisateur!$U$3,"") | K19: =IF('calcul des chants'!H33=Optimisateur!$T$3,Optimisateur!$U$3,"") | M19: =IF(C19="","",'calcul des chants'!$C$4) | N19: =IF(D19="","",'calcul des chants'!$Z$4) | O19: =IF(E19="","",'calcul des chants'!J33) | P19: =IF(F19="","",'calcul des chants'!M33) | Q19: =IF(G19="","",'calcul des chants'!P33)
B20: =IF(D20="","",'calcul des chants'!A34) | C20: =IF('calcul des chants'!B34<>"",'calcul des chants'!$A$10,"") | D20: =IF(C20="","",'calcul des chants'!B34) | E20: =IF(D20="","",'calcul des chants'!C34) | F20: =IF(E20="","",'calcul des chants'!D34) | H20: =IF('calcul des chants'!E34=Optimisateur!$T$3,Optimisateur!$U$3,"") | I20: =IF('calcul des chants'!F34=Optimisateur!$T$3,Optimisateur!$U$3,"") | J20: =IF('calcul des chants'!G34=Optimisateur!$T$3,Optimisateur!$U$3,"") | K20: =IF('calcul des chants'!H34=Optimisateur!$T$3,Optimisateur!$U$3,"") | M20: =IF(C20="","",'calcul des chants'!$C$4) | N20: =IF(D20="","",'calcul des chants'!$Z$4) | O20: =IF(E20="","",'calcul des chants'!J34) | P20: =IF(F20="","",'calcul des chants'!M34) | Q20: =IF(G20="","",'calcul des chants'!P34)
B21: =IF(D21="","",'calcul des chants'!A35) | C21: =IF('calcul des chants'!B35<>"",'calcul des chants'!$A$10,"") | D21: =IF(C21="","",'calcul des chants'!B35) | E21: =IF(D21="","",'calcul des chants'!C35) | F21: =IF(E21="","",'calcul des chants'!D35) | H21: =IF('calcul des chants'!E35=Optimisateur!$T$3,Optimisateur!$U$3,"") | I21: =IF('calcul des chants'!F35=Optimisateur!$T$3,Optimisateur!$U$3,"") | J21: =IF('calcul des chants'!G35=Optimisateur!$T$3,Optimisateur!$U$3,"") | K21: =IF('calcul des chants'!H35=Optimisateur!$T$3,Optimisateur!$U$3,"") | M21: =IF(C21="","",'calcul des chants'!$C$4) | N21: =IF(D21="","",'calcul des chants'!$Z$4) | O21: =IF(E21="","",'calcul des chants'!J35) | P21: =IF(F21="","",'calcul des chants'!M35) | Q21: =IF(G21="","",'calcul des chants'!P35)
B22: =IF(D22="","",'calcul des chants'!A36) | C22: =IF('calcul des chants'!B36<>"",'calcul des chants'!$A$10,"") | D22: =IF(C22="","",'calcul des chants'!B36) | E22: =IF(D22="","",'calcul des chants'!C36) | F22: =IF(E22="","",'calcul des chants'!D36) | H22: =IF('calcul des chants'!E36=Optimisateur!$T$3,Optimisateur!$U$3,"") | I22: =IF('calcul des chants'!F36=Optimisateur!$T$3,Optimisateur!$U$3,"") | J22: =IF('calcul des chants'!G36=Optimisateur!$T$3,Optimisateur!$U$3,"") | K22: =IF('calcul des chants'!H36=Optimisateur!$T$3,Optimisateur!$U$3,"") | M22: =IF(C22="","",'calcul des chants'!$C$4) | N22: =IF(D22="","",'calcul des chants'!$Z$4) | O22: =IF(E22="","",'calcul des chants'!J36) | P22: =IF(F22="","",'calcul des chants'!M36) | Q22: =IF(G22="","",'calcul des chants'!P36)
B23: =IF(D23="","",'calcul des chants'!A37) | C23: =IF('calcul des chants'!B37<>"",'calcul des chants'!$A$10,"") | D23: =IF(C23="","",'calcul des chants'!B37) | E23: =IF(D23="","",'calcul des chants'!C37) | F23: =IF(E23="","",'calcul des chants'!D37) | H23: =IF('calcul des chants'!E37=Optimisateur!$T$3,Optimisateur!$U$3,"") | I23: =IF('calcul des chants'!F37=Optimisateur!$T$3,Optimisateur!$U$3,"") | J23: =IF('calcul des chants'!G37=Optimisateur!$T$3,Optimisateur!$U$3,"") | K23: =IF('calcul des chants'!H37=Optimisateur!$T$3,Optimisateur!$U$3,"") | M23: =IF(C23="","",'calcul des chants'!$C$4) | N23: =IF(D23="","",'calcul des chants'!$Z$4) | O23: =IF(E23="","",'calcul des chants'!J37) | P23: =IF(F23="","",'calcul des chants'!M37) | Q23: =IF(G23="","",'calcul des chants'!P37)
B24: =IF(D24="","",'calcul des chants'!A38) | C24: =IF('calcul des chants'!B38<>"",'calcul des chants'!$A$10,"") | D24: =IF(C24="","",'calcul des chants'!B38) | E24: =IF(D24="","",'calcul des chants'!C38) | F24: =IF(E24="","",'calcul des chants'!D38) | H24: =IF('calcul des chants'!E38=Optimisateur!$T$3,Optimisateur!$U$3,"") | I24: =IF('calcul des chants'!F38=Optimisateur!$T$3,Optimisateur!$U$3,"") | J24: =IF('calcul des chants'!G38=Optimisateur!$T$3,Optimisateur!$U$3,"") | K24: =IF('calcul des chants'!H38=Optimisateur!$T$3,Optimisateur!$U$3,"") | M24: =IF(C24="","",'calcul des chants'!$C$4) | N24: =IF(D24="","",'calcul des chants'!$Z$4) | O24: =IF(E24="","",'calcul des chants'!J38) | P24: =IF(F24="","",'calcul des chants'!M38) | Q24: =IF(G24="","",'calcul des chants'!P38)
B25: =IF(D25="","",'calcul des chants'!A39) | C25: =IF('calcul des chants'!B39<>"",'calcul des chants'!$A$10,"") | D25: =IF(C25="","",'calcul des chants'!B39) | E25: =IF(D25="","",'calcul des chants'!C39) | F25: =IF(E25="","",'calcul des chants'!D39) | H25: =IF('calcul des chants'!E39=Optimisateur!$T$3,Optimisateur!$U$3,"") | I25: =IF('calcul des chants'!F39=Optimisateur!$T$3,Optimisateur!$U$3,"") | J25: =IF('calcul des chants'!G39=Optimisateur!$T$3,Optimisateur!$U$3,"") | K25: =IF('calcul des chants'!H39=Optimisateur!$T$3,Optimisateur!$U$3,"") | M25: =IF(C25="","",'calcul des chants'!$C$4) | N25: =IF(D25="","",'calcul des chants'!$Z$4) | O25: =IF(E25="","",'calcul des chants'!J39) | P25: =IF(F25="","",'calcul des chants'!M39) | Q25: =IF(G25="","",'calcul des chants'!P39)
B26: =IF(D26="","",'calcul des chants'!A40) | C26: =IF('calcul des chants'!B40<>"",'calcul des chants'!$A$10,"") | D26: =IF(C26="","",'calcul des chants'!B40) | E26: =IF(D26="","",'calcul des chants'!C40) | F26: =IF(E26="","",'calcul des chants'!D40) | H26: =IF('calcul des chants'!E40=Optimisateur!$T$3,Optimisateur!$U$3,"") | I26: =IF('calcul des chants'!F40=Optimisateur!$T$3,Optimisateur!$U$3,"") | J26: =IF('calcul des chants'!G40=Optimisateur!$T$3,Optimisateur!$U$3,"") | K26: =IF('calcul des chants'!H40=Optimisateur!$T$3,Optimisateur!$U$3,"") | M26: =IF(C26="","",'calcul des chants'!$C$4) | N26: =IF(D26="","",'calcul des chants'!$Z$4) | O26: =IF(E26="","",'calcul des chants'!J40) | P26: =IF(F26="","",'calcul des chants'!M40) | Q26: =IF(G26="","",'calcul des chants'!P40)
... B29: =IF(D29="","",'calcul des chants'!A43) | C29: =IF('calcul des chants'!B43<>"",'calcul des chants'!$A$10,"") | D29: =IF(C29="","",'calcul des chants'!B43) | E29: =IF(D29="","",'calcul des chants'!C43) | F29: =IF(E29="","",'calcul des chants'!D43) | H29: =IF('calcul des chants'!E43=Optimisateur!$T$3,Optimisateur!$U$3,"") | I29: =IF('calcul des chants'!F43=Optimisateur!$T$3,Optimisateur!$U$3,"") | J29: =IF('calcul des chants'!G43=Optimisateur!$T$3,Optimisateur!$U$3,"") | K29: =IF('calcul des chants'!H43=Optimisateur!$T$3,Optimisateur!$U$3,"") | M29: =IF(C29="","",'calcul des chants'!$C$4) | N29: =IF(D29="","",'calcul des chants'!$Z$4) | O29: =IF(E29="","",'calcul des chants'!J43) | P29: =IF(F29="","",'calcul des chants'!M43) | Q29: =IF(G29="","",'calcul des chants'!P43)
B30: =IF(D30="","",'calcul des chants'!A56) | C30: =IF('calcul des chants'!B79<>"",'calcul des chants'!$A$10,"") | D30: =IF(C30="","",'calcul des chants'!B79) | E30: =IF(D30="","",'calcul des chants'!C79) | F30: =IF(E30="","",'calcul des chants'!D79) | H30: =IF('calcul des chants'!E79=Optimisateur!$T$3,Optimisateur!$U$3,"") | I30: =IF('calcul des chants'!F79=Optimisateur!$T$3,Optimisateur!$U$3,"") | J30: =IF('calcul des chants'!G79=Optimisateur!$T$3,Optimisateur!$U$3,"") | K30: =IF('calcul des chants'!H79=Optimisateur!$T$3,Optimisateur!$U$3,"") | M30: =IF(C30="","",'calcul des chants'!$C$4) | N30: =IF(D30="","",'calcul des chants'!$Z$4) | O30: =IF(E30="","",'calcul des chants'!J79) | P30: =IF(F30="","",'calcul des chants'!M79) | Q30: =IF(G30="","",'calcul des chants'!P79)
B31: =IF(D31="","",'calcul des chants'!A57) | C31: =IF('calcul des chants'!B80<>"",'calcul des chants'!$A$10,"") | D31: =IF(C31="","",'calcul des chants'!B80) | E31: =IF(D31="","",'calcul des chants'!C80) | F31: =IF(E31="","",'calcul des chants'!D80) | H31: =IF('calcul des chants'!E80=Optimisateur!$T$3,Optimisateur!$U$3,"") | I31: =IF('calcul des chants'!F80=Optimisateur!$T$3,Optimisateur!$U$3,"") | J31: =IF('calcul des chants'!G80=Optimisateur!$T$3,Optimisateur!$U$3,"") | K31: =IF('calcul des chants'!H80=Optimisateur!$T$3,Optimisateur!$U$3,"") | M31: =IF(C31="","",'calcul des chants'!$C$4) | N31: =IF(D31="","",'calcul des chants'!$Z$4) | O31: =IF(E31="","",'calcul des chants'!J80) | P31: =IF(F31="","",'calcul des chants'!M80) | Q31: =IF(G31="","",'calcul des chants'!P80)
B32: =IF(D32="","",'calcul des chants'!A58) | C32: =IF('calcul des chants'!B81<>"",'calcul des chants'!$A$10,"") | D32: =IF(C32="","",'calcul des chants'!B81) | E32: =IF(D32="","",'calcul des chants'!C81) | F32: =IF(E32="","",'calcul des chants'!D81) | H32: =IF('calcul des chants'!E81=Optimisateur!$T$3,Optimisateur!$U$3,"") | I32: =IF('calcul des chants'!F81=Optimisateur!$T$3,Optimisateur!$U$3,"") | J32: =IF('calcul des chants'!G81=Optimisateur!$T$3,Optimisateur!$U$3,"") | K32: =IF('calcul des chants'!H81=Optimisateur!$T$3,Optimisateur!$U$3,"") | M32: =IF(C32="","",'calcul des chants'!$C$4) | N32: =IF(D32="","",'calcul des chants'!$Z$4) | O32: =IF(E32="","",'calcul des chants'!J81) | P32: =IF(F32="","",'calcul des chants'!M81) | Q32: =IF(G32="","",'calcul des chants'!P81)
B33: =IF(D33="","",'calcul des chants'!A59) | C33: =IF('calcul des chants'!B82<>"",'calcul des chants'!$A$10,"") | D33: =IF(C33="","",'calcul des chants'!B82) | E33: =IF(D33="","",'calcul des chants'!C82) | F33: =IF(E33="","",'calcul des chants'!D82) | H33: =IF('calcul des chants'!E82=Optimisateur!$T$3,Optimisateur!$U$3,"") | I33: =IF('calcul des chants'!F82=Optimisateur!$T$3,Optimisateur!$U$3,"") | J33: =IF('calcul des chants'!G82=Optimisateur!$T$3,Optimisateur!$U$3,"") | K33: =IF('calcul des chants'!H82=Optimisateur!$T$3,Optimisateur!$U$3,"") | M33: =IF(C33="","",'calcul des chants'!$C$4) | N33: =IF(D33="","",'calcul des chants'!$Z$4) | O33: =IF(E33="","",'calcul des chants'!J82) | P33: =IF(F33="","",'calcul des chants'!M82) | Q33: =IF(G33="","",'calcul des chants'!P82)
B34: =IF(D34="","",'calcul des chants'!A60) | C34: =IF('calcul des chants'!B83<>"",'calcul des chants'!$A$10,"") | D34: =IF(C34="","",'calcul des chants'!B83) | E34: =IF(D34="","",'calcul des chants'!C83) | F34: =IF(E34="","",'calcul des chants'!D83) | H34: =IF('calcul des chants'!E83=Optimisateur!$T$3,Optimisateur!$U$3,"") | I34: =IF('calcul des chants'!F83=Optimisateur!$T$3,Optimisateur!$U$3,"") | J34: =IF('calcul des chants'!G83=Optimisateur!$T$3,Optimisateur!$U$3,"") | K34: =IF('calcul des chants'!H83=Optimisateur!$T$3,Optimisateur!$U$3,"") | M34: =IF(C34="","",'calcul des chants'!$C$4) | N34: =IF(D34="","",'calcul des chants'!$Z$4) | O34: =IF(E34="","",'calcul des chants'!J83) | P34: =IF(F34="","",'calcul des chants'!M83) | Q34: =IF(G34="","",'calcul des chants'!P83)
B35: =IF(D35="","",'calcul des chants'!A75) | C35: =IF('calcul des chants'!B84<>"",'calcul des chants'!$A$10,"") | D35: =IF(C35="","",'calcul des chants'!B84) | E35: =IF(D35="","",'calcul des chants'!C84) | F35: =IF(E35="","",'calcul des chants'!D84) | H35: =IF('calcul des chants'!E84=Optimisateur!$T$3,Optimisateur!$U$3,"") | I35: =IF('calcul des chants'!F84=Optimisateur!$T$3,Optimisateur!$U$3,"") | J35: =IF('calcul des chants'!G84=Optimisateur!$T$3,Optimisateur!$U$3,"") | K35: =IF('calcul des chants'!H84=Optimisateur!$T$3,Optimisateur!$U$3,"") | M35: =IF(C35="","",'calcul des chants'!$C$4) | N35: =IF(D35="","",'calcul des chants'!$Z$4) | O35: =IF(E35="","",'calcul des chants'!J84) | P35: =IF(F35="","",'calcul des chants'!M84) | Q35: =IF(G35="","",'calcul des chants'!P84)
B36: =IF(D36="","",'calcul des chants'!A76) | C36: =IF('calcul des chants'!B85<>"",'calcul des chants'!$A$10,"") | D36: =IF(C36="","",'calcul des chants'!B85) | E36: =IF(D36="","",'calcul des chants'!C85) | F36: =IF(E36="","",'calcul des chants'!D85) | H36: =IF('calcul des chants'!E85=Optimisateur!$T$3,Optimisateur!$U$3,"") | I36: =IF('calcul des chants'!F85=Optimisateur!$T$3,Optimisateur!$U$3,"") | J36: =IF('calcul des chants'!G85=Optimisateur!$T$3,Optimisateur!$U$3,"") | K36: =IF('calcul des chants'!H85=Optimisateur!$T$3,Optimisateur!$U$3,"") | M36: =IF(C36="","",'calcul des chants'!$C$4) | N36: =IF(D36="","",'calcul des chants'!$Z$4) | O36: =IF(E36="","",'calcul des chants'!J85) | P36: =IF(F36="","",'calcul des chants'!M85) | Q36: =IF(G36="","",'calcul des chants'!P85)
B37: =IF(D37="","",'calcul des chants'!A77) | C37: =IF('calcul des chants'!B86<>"",'calcul des chants'!$A$10,"") | D37: =IF(C37="","",'calcul des chants'!B86) | E37: =IF(D37="","",'calcul des chants'!C86) | F37: =IF(E37="","",'calcul des chants'!D86) | H37: =IF('calcul des chants'!E86=Optimisateur!$T$3,Optimisateur!$U$3,"") | I37: =IF('calcul des chants'!F86=Optimisateur!$T$3,Optimisateur!$U$3,"") | J37: =IF('calcul des chants'!G86=Optimisateur!$T$3,Optimisateur!$U$3,"") | K37: =IF('calcul des chants'!H86=Optimisateur!$T$3,Optimisateur!$U$3,"") | M37: =IF(C37="","",'calcul des chants'!$C$4) | N37: =IF(D37="","",'calcul des chants'!$Z$4) | O37: =IF(E37="","",'calcul des chants'!J86) | P37: =IF(F37="","",'calcul des chants'!M86) | Q37: =IF(G37="","",'calcul des chants'!P86)
B38: =IF(D38="","",'calcul des chants'!A78) | C38: =IF('calcul des chants'!B87<>"",'calcul des chants'!$A$10,"") | D38: =IF(C38="","",'calcul des chants'!B87) | E38: =IF(D38="","",'calcul des chants'!C87) | F38: =IF(E38="","",'calcul des chants'!D87) | H38: =IF('calcul des chants'!E87=Optimisateur!$T$3,Optimisateur!$U$3,"") | I38: =IF('calcul des chants'!F87=Optimisateur!$T$3,Optimisateur!$U$3,"") | J38: =IF('calcul des chants'!G87=Optimisateur!$T$3,Optimisateur!$U$3,"") | K38: =IF('calcul des chants'!H87=Optimisateur!$T$3,Optimisateur!$U$3,"") | M38: =IF(C38="","",'calcul des chants'!$C$4) | N38: =IF(D38="","",'calcul des chants'!$Z$4) | O38: =IF(E38="","",'calcul des chants'!J87) | P38: =IF(F38="","",'calcul des chants'!M87) | Q38: =IF(G38="","",'calcul des chants'!P87)
B39: =IF(D39="","",'calcul des chants'!#REF!) | C39: =IF('calcul des chants'!B88<>"",'calcul des chants'!$A$10,"") | D39: =IF(C39="","",'calcul des chants'!B88) | E39: =IF(D39="","",'calcul des chants'!C88) | F39: =IF(E39="","",'calcul des chants'!D88) | H39: =IF('calcul des chants'!E88=Optimisateur!$T$3,Optimisateur!$U$3,"") | I39: =IF('calcul des chants'!F88=Optimisateur!$T$3,Optimisateur!$U$3,"") | J39: =IF('calcul des chants'!G88=Optimisateur!$T$3,Optimisateur!$U$3,"") | K39: =IF('calcul des chants'!H88=Optimisateur!$T$3,Optimisateur!$U$3,"") | M39: =IF(C39="","",'calcul des chants'!$C$4) | N39: =IF(D39="","",'calcul des chants'!$Z$4) | O39: =IF(E39="","",'calcul des chants'!J88) | P39: =IF(F39="","",'calcul des chants'!M88) | Q39: =IF(G39="","",'calcul des chants'!P88)
B40: =IF(D40="","",'calcul des chants'!#REF!) | C40: =IF('calcul des chants'!B89<>"",'calcul des chants'!$A$10,"") | D40: =IF(C40="","",'calcul des chants'!B89) | E40: =IF(D40="","",'calcul des chants'!C89) | F40: =IF(E40="","",'calcul des chants'!D89) | H40: =IF('calcul des chants'!E89=Optimisateur!$T$3,Optimisateur!$U$3,"") | I40: =IF('calcul des chants'!F89=Optimisateur!$T$3,Optimisateur!$U$3,"") | J40: =IF('calcul des chants'!G89=Optimisateur!$T$3,Optimisateur!$U$3,"") | K40: =IF('calcul des chants'!H89=Optimisateur!$T$3,Optimisateur!$U$3,"") | M40: =IF(C40="","",'calcul des chants'!$C$4) | N40: =IF(D40="","",'calcul des chants'!$Z$4) | O40: =IF(E40="","",'calcul des chants'!J89) | P40: =IF(F40="","",'calcul des chants'!M89) | Q40: =IF(G40="","",'calcul des chants'!P89)
B41: =IF(D41="","",'calcul des chants'!#REF!) | C41: =IF('calcul des chants'!B90<>"",'calcul des chants'!$A$10,"") | D41: =IF(C41="","",'calcul des chants'!B90) | E41: =IF(D41="","",'calcul des chants'!C90) | F41: =IF(E41="","",'calcul des chants'!D90) | H41: =IF('calcul des chants'!E90=Optimisateur!$T$3,Optimisateur!$U$3,"") | I41: =IF('calcul des chants'!F90=Optimisateur!$T$3,Optimisateur!$U$3,"") | J41: =IF('calcul des chants'!G90=Optimisateur!$T$3,Optimisateur!$U$3,"") | K41: =IF('calcul des chants'!H90=Optimisateur!$T$3,Optimisateur!$U$3,"") | M41: =IF(C41="","",'calcul des chants'!$C$4) | N41: =IF(D41="","",'calcul des chants'!$Z$4) | O41: =IF(E41="","",'calcul des chants'!J90) | P41: =IF(F41="","",'calcul des chants'!M90) | Q41: =IF(G41="","",'calcul des chants'!P90)
B42: =IF(D42="","",'calcul des chants'!#REF!) | C42: =IF('calcul des chants'!B91<>"",'calcul des chants'!$A$10,"") | D42: =IF(C42="","",'calcul des chants'!B91) | E42: =IF(D42="","",'calcul des chants'!C91) | F42: =IF(E42="","",'calcul des chants'!D91) | H42: =IF('calcul des chants'!E91=Optimisateur!$T$3,Optimisateur!$U$3,"") | I42: =IF('calcul des chants'!F91=Optimisateur!$T$3,Optimisateur!$U$3,"") | J42: =IF('calcul des chants'!G91=Optimisateur!$T$3,Optimisateur!$U$3,"") | K42: =IF('calcul des chants'!H91=Optimisateur!$T$3,Optimisateur!$U$3,"") | M42: =IF(C42="","",'calcul des chants'!$C$4) | N42: =IF(D42="","",'calcul des chants'!$Z$4) | O42: =IF(E42="","",'calcul des chants'!J91) | P42: =IF(F42="","",'calcul des chants'!M91) | Q42: =IF(G42="","",'calcul des chants'!P91)
B43: =IF(D43="","",'calcul des chants'!A79) | C43: =IF('calcul des chants'!B92<>"",'calcul des chants'!$A$10,"") | D43: =IF(C43="","",'calcul des chants'!B92) | E43: =IF(D43="","",'calcul des chants'!C92) | F43: =IF(E43="","",'calcul des chants'!D92) | H43: =IF('calcul des chants'!E92=Optimisateur!$T$3,Optimisateur!$U$3,"") | I43: =IF('calcul des chants'!F92=Optimisateur!$T$3,Optimisateur!$U$3,"") | J43: =IF('calcul des chants'!G92=Optimisateur!$T$3,Optimisateur!$U$3,"") | K43: =IF('calcul des chants'!H92=Optimisateur!$T$3,Optimisateur!$U$3,"") | M43: =IF(C43="","",'calcul des chants'!$C$4) | N43: =IF(D43="","",'calcul des chants'!$Z$4) | O43: =IF(E43="","",'calcul des chants'!J92) | P43: =IF(F43="","",'calcul des chants'!M92) | Q43: =IF(G43="","",'calcul des chants'!P92)
...
